Workbook
Name Slicer_price_range: #N/A
Name Slicer_price_range1: #N/A
Name Slicer_Range: #N/A
Name Slicer_task5_range: #N/A

Sheet raw data
A1: Coin Name | B1: Symbol | C1: Price (USD) | D1: 1h Change (%) | E1: 1h change | F1: 24 hr change | G1: 7d change | H1: Market Cap | I1: Volume (24h) USD | J1: volume num | K1: Circulating Supply | L1: Allowed coin | M1: current price | N1: previous price | O1: price range | P1: price change | Q1: average downfall | R1: task5 range | S1: Range
A2: Bitcoin | B2: BTC | C2: $104,058.04 | D2: 0.0024 | E2: =D2 -> 0.0024 | F2: =-D2 -> -0.0024 | G2: =D2 -> 0.0024 | H2: $2.07T | I2: $43,170,391,288 | J2: =IFERROR(VALUE(SUBSTITUTE(SUBSTITUTE(Table1[[#This Row],[Volume (24h) USD]],"$",""),",","")),0) -> 43170391288 | K2: 19.88M | L2: =IF(OR(LEFT(Table1[[#This Row],[Coin Name]],1)="A",LEFT(Table1[[#This Row],[Coin Name]],1)="E",LEFT(Table1[[#This Row],[Coin Name]],1)="I",LEFT(Table1[[#This Row],[Coin Name]],1)="O",LEFT(Table1[[#This Row],[Coin Name]],1)="U",LEFT(Table1[[#This Row],[Coin Name]],1)="B",LEFT(Table1[[#This Row],[Coin Name]],1)="C",LEFT(Table1[[#This Row],[Coin Name]],1)="D"),"Yes","No") -> Yes | M2: =VALUE(SUBSTITUTE(C2,"$","")) -> 104058.04 | N2: =M2/(1+D2) -> 103808.9 | O2: =IF(M2<10,"Up to $10",">= $10") -> >= $10 | P2: =M2-N2 -> 249.14136 | Q2: =F2 -> -0.0024 | R2: =IF(M2<=5,"$0-$5",">$5") -> >$5 | S2: =IF(M2<=0.05,"$0-$0.05",IF(M2<=0.5,"$0.05-$0.5",IF(M2<=5,"$0.5-$5",IF(M2<=50,"$5-$50",">$50")))) -> >$50
A3: Ethereum | B3: ETH | C3: $2,483.59 | D3: 0.0076 | E3: =D3 -> 0.0076 | F3: =-D3 -> -0.0076 | G3: =D3 -> 0.0076 | H3: $299.51B | I3: $14,942,260,356 | J3: =IFERROR(VALUE(SUBSTITUTE(SUBSTITUTE(Table1[[#This Row],[Volume (24h) USD]],"$",""),",","")),0) -> 14942260356 | K3: 120.72M | L3: =IF(OR(LEFT(Table1[[#This Row],[Coin Name]],1)="A",LEFT(Table1[[#This Row],[Coin Name]],1)="E",LEFT(Table1[[#This Row],[Coin Name]],1)="I",LEFT(Table1[[#This Row],[Coin Name]],1)="O",LEFT(Table1[[#This Row],[Coin Name]],1)="U",LEFT(Table1[[#This Row],[Coin Name]],1)="B",LEFT(Table1[[#This Row],[Coin Name]],1)="C",LEFT(Table1[[#This Row],[Coin Name]],1)="D"),"Yes","No") -> Yes | M3: =VALUE(SUBSTITUTE(C3,"$","")) -> 2483.59 | N3: =M3/(1+D3) -> 2464.8571 | O3: =IF(M3<10,"Up to $10",">= $10") -> >= $10 | P3: =M3-N3 -> 18.732914 | Q3: =F3 -> -0.0076 | R3: =IF(M3<=5,"$0-$5",">$5") -> >$5 | S3: =IF(M3<=0.05,"$0-$0.05",IF(M3<=0.5,"$0.05-$0.5",IF(M3<=5,"$0.5-$5",IF(M3<=50,"$5-$50",">$50")))) -> >$50
A4: Tether | B4: USDT | C4: $0.9999 | D4: 0.0004 | E4: =D4 -> 0.0004 | F4: =-D4 -> -0.0004 | G4: =D4 -> 0.0004 | H4: $155.95B | I4: $60,772,601,456 | J4: =IFERROR(VALUE(SUBSTITUTE(SUBSTITUTE(Table1[[#This Row],[Volume (24h) USD]],"$",""),",","")),0) -> 60772601456 | K4: 155.94B | L4: =IF(OR(LEFT(Table1[[#This Row],[Coin Name]],1)="A",LEFT(Table1[[#This Row],[Coin Name]],1)="E",LEFT(Table1[[#This Row],[Coin Name]],1)="I",LEFT(Table1[[#This Row],[Coin Name]],1)="O",LEFT(Table1[[#This Row],[Coin Name]],1)="U",LEFT(Table1[[#This Row],[Coin Name]],1)="B",LEFT(Table1[[#This Row],[Coin Name]],1)="C",LEFT(Table1[[#This Row],[Coin Name]],1)="D"),"Yes","No") -> No | M4: =VALUE(SUBSTITUTE(C4,"$","")) -> 0.9999 | N4: =M4/(1+D4) -> 0.9995002 | O4: =IF(M4<10,"Up to $10",">= $10") -> Up to $10 | P4: =M4-N4 -> 0.00039980008 | Q4: =F4 -> -0.0004 | R4: =IF(M4<=5,"$0-$5",">$5") -> $0-$5 | S4: =IF(C4<=0.05,"$0-$0.05", IF(C4<=0.5,"$0.05-$0.5", IF(C4<=5,"$0.5-$5", IF(C4<=50,"$5-$50",">$50")))) -> >$50
A5: XRP | B5: XRP | C5: $2.12 | D5: 0.0055 | E5: =D5 -> 0.0055 | F5: =-D5 -> -0.0055 | G5: =D5 -> 0.0055 | H5: $125.42B | I5: $2,046,333,328 | J5: =IFERROR(VALUE(SUBSTITUTE(SUBSTITUTE(Table1[[#This Row],[Volume (24h) USD]],"$",""),",","")),0) -> 2046333328 | K5: 58.93B | L5: =IF(OR(LEFT(Table1[[#This Row],[Coin Name]],1)="A",LEFT(Table1[[#This Row],[Coin Name]],1)="E",LEFT(Table1[[#This Row],[Coin Name]],1)="I",LEFT(Table1[[#This Row],[Coin Name]],1)="O",LEFT(Table1[[#This Row],[Coin Name]],1)="U",LEFT(Table1[[#This Row],[Coin Name]],1)="B",LEFT(Table1[[#This Row],[Coin Name]],1)="C",LEFT(Table1[[#This Row],[Coin Name]],1)="D"),"Yes","No") -> No | M5: =VALUE(SUBSTITUTE(C5,"$","")) -> 2.12 | N5: =M5/(1+D5) -> 2.1084038 | O5: =IF(M5<10,"Up to $10",">= $10") -> Up to $10 | P5: =M5-N5 -> 0.011596221 | Q5: =F5 -> -0.0055 | R5: =IF(M5<=5,"$0-$5",">$5") -> $0-$5 | S5: =IF(C5<=0.05,"$0-$0.05", IF(C5<=0.5,"$0.05-$0.5", IF(C5<=5,"$0.5-$5", IF(C5<=50,"$5-$50",">$50")))) -> >$50
A6: USDC | B6: USDC | C6: $0.9998 | D6: 0.0003 | E6: =D6 -> 0.0003 | F6: =-D6 -> -0.0003 | G6: =D6 -> 0.0003 | H6: $61.23B | I6: $8,208,315,257 | J6: =IFERROR(VALUE(SUBSTITUTE(SUBSTITUTE(Table1[[#This Row],[Volume (24h) USD]],"$",""),",","")),0) -> 8208315257 | K6: 61.23B | L6: =IF(OR(LEFT(Table1[[#This Row],[Coin Name]],1)="A",LEFT(Table1[[#This Row],[Coin Name]],1)="E",LEFT(Table1[[#This Row],[Coin Name]],1)="I",LEFT(Table1[[#This Row],[Coin Name]],1)="O",LEFT(Table1[[#This Row],[Coin Name]],1)="U",LEFT(Table1[[#This Row],[Coin Name]],1)="B",LEFT(Table1[[#This Row],[Coin Name]],1)="C",LEFT(Table1[[#This Row],[Coin Name]],1)="D"),"Yes","No") -> Yes | M6: =VALUE(SUBSTITUTE(C6,"$","")) -> 0.9998 | N6: =M6/(1+D6) -> 0.99950015 | O6: =IF(M6<10,"Up to $10",">= $10") -> Up to $10 | P6: =M6-N6 -> 0.00029985004 | Q6: =F6 -> -0.0003 | R6: =IF(M6<=5,"$0-$5",">$5") -> $0-$5 | S6: =IF(M6<=0.05,"$0-$0.05",IF(M6<=0.5,"$0.05-$0.5",IF(M6<=5,"$0.5-$5",IF(M6<=50,"$5-$50",">$50")))) -> $0.5-$5
A7: Solana | B7: SOL | C7: $142.67 | D7: 0.0099 | E7: =D7 -> 0.0099 | F7: =-D7 -> -0.0099 | G7: =D7 -> 0.0099 | H7: $75.33B | I7: $2,904,341,748 | J7: =IFERROR(VALUE(SUBSTITUTE(SUBSTITUTE(Table1[[#This Row],[Volume (24h) USD]],"$",""),",","")),0) -> 2904341748 | K7: 527.96M | L7: =IF(OR(LEFT(Table1[[#This Row],[Coin Name]],1)="A",LEFT(Table1[[#This Row],[Coin Name]],1)="E",LEFT(Table1[[#This Row],[Coin Name]],1)="I",LEFT(Table1[[#This Row],[Coin Name]],1)="O",LEFT(Table1[[#This Row],[Coin Name]],1)="U",LEFT(Table1[[#This Row],[Coin Name]],1)="B",LEFT(Table1[[#This Row],[Coin Name]],1)="C",LEFT(Table1[[#This Row],[Coin Name]],1)="D"),"Yes","No") -> No | M7: =VALUE(SUBSTITUTE(C7,"$","")) -> 142.67 | N7: =M7/(1+D7) -> 141.27141 | O7: =IF(M7<10,"Up to $10",">= $10") -> >= $10 | P7: =M7-N7 -> 1.398587 | Q7: =F7 -> -0.0099 | R7: =IF(M7<=5,"$0-$5",">$5") -> >$5 | S7: =IF(C7<=0.05,"$0-$0.05", IF(C7<=0.5,"$0.05-$0.5", IF(C7<=5,"$0.5-$5", IF(C7<=50,"$5-$50",">$50")))) -> >$50
A8: BNB | B8: BNB | C8: $644.79 | D8: 0.001 | E8: =D8 -> 0.001 | F8: =-D8 -> -0.001 | G8: =D8 -> 0.001 | H8: $90.84B | I8: $1,497,928,447 | J8: =IFERROR(VALUE(SUBSTITUTE(SUBSTITUTE(Table1[[#This Row],[Volume (24h) USD]],"$",""),",","")),0) -> 1497928447 | K8: 140.88M | L8: =IF(OR(LEFT(Table1[[#This Row],[Coin Name]],1)="A",LEFT(Table1[[#This Row],[Coin Name]],1)="E",LEFT(Table1[[#This Row],[Coin Name]],1)="I",LEFT(Table1[[#This Row],[Coin Name]],1)="O",LEFT(Table1[[#This Row],[Coin Name]],1)="U",LEFT(Table1[[#This Row],[Coin Name]],1)="B",LEFT(Table1[[#This Row],[Coin Name]],1)="C",LEFT(Table1[[#This Row],[Coin Name]],1)="D"),"Yes","No") -> Yes | M8: =VALUE(SUBSTITUTE(C8,"$","")) -> 644.79 | N8: =M8/(1+D8) -> 644.14585 | O8: =IF(M8<10,"Up to $10",">= $10") -> >= $10 | P8: =M8-N8 -> 0.64414585 | Q8: =F8 -> -0.001 | R8: =IF(M8<=5,"$0-$5",">$5") -> >$5 | S8: =IF(M8<=0.05,"$0-$0.05",IF(M8<=0.5,"$0.05-$0.5",IF(M8<=5,"$0.5-$5",IF(M8<=50,"$5-$50",">$50")))) -> >$50
A9: TRON | B9: TRX | C9: $0.2734 | D9: 0.0036 | E9: =D9 -> 0.0036 | F9: =-D9 -> -0.0036 | G9: =D9 -> 0.0036 | H9: $25.93B | I9: $445,406,337 | J9: =IFERROR(VALUE(SUBSTITUTE(SUBSTITUTE(Table1[[#This Row],[Volume (24h) USD]],"$",""),",","")),0) -> 445406337 | K9: 94.82B | L9: =IF(OR(LEFT(Table1[[#This Row],[Coin Name]],1)="A",LEFT(Table1[[#This Row],[Coin Name]],1)="E",LEFT(Table1[[#This Row],[Coin Name]],1)="I",LEFT(Table1[[#This Row],[Coin Name]],1)="O",LEFT(Table1[[#This Row],[Coin Name]],1)="U",LEFT(Table1[[#This Row],[Coin Name]],1)="B",LEFT(Table1[[#This Row],[Coin Name]],1)="C",LEFT(Table1[[#This Row],[Coin Name]],1)="D"),"Yes","No") -> No | M9: =VALUE(SUBSTITUTE(C9,"$","")) -> 0.2734 | N9: =M9/(1+D9) -> 0.27241929 | O9: =IF(M9<10,"Up to $10",">= $10") -> Up to $10 | P9: =M9-N9 -> 0.00098070945 | Q9: =F9 -> -0.0036 | R9: =IF(M9<=5,"$0-$5",">$5") -> $0-$5 | S9: =IF(C9<=0.05,"$0-$0.05", IF(C9<=0.5,"$0.05-$0.5", IF(C9<=5,"$0.5-$5", IF(C9<=50,"$5-$50",">$50")))) -> >$50
A10: Dogecoin | B10: DOGE | C10: $0.1654 | D10: 0.0094 | E10: =D10 -> 0.0094 | F10: =-D10 -> -0.0094 | G10: =D10 -> 0.0094 | H10: $24.77B | I10: $781,433,558 | J10: =IFERROR(VALUE(SUBSTITUTE(SUBSTITUTE(Table1[[#This Row],[Volume (24h) USD]],"$",""),",","")),0) -> 781433558 | K10: 149.76B | L10: =IF(OR(LEFT(Table1[[#This Row],[Coin Name]],1)="A",LEFT(Table1[[#This Row],[Coin Name]],1)="E",LEFT(Table1[[#This Row],[Coin Name]],1)="I",LEFT(Table1[[#This Row],[Coin Name]],1)="O",LEFT(Table1[[#This Row],[Coin Name]],1)="U",LEFT(Table1[[#This Row],[Coin Name]],1)="B",LEFT(Table1[[#This Row],[Coin Name]],1)="C",LEFT(Table1[[#This Row],[Coin Name]],1)="D"),"Yes","No") -> Yes | M10: =VALUE(SUBSTITUTE(C10,"$","")) -> 0.1654 | N10: =M10/(1+D10) -> 0.16385972 | O10: =IF(M10<10,"Up to $10",">= $10") -> Up to $10 | P10: =M10-N10 -> 0.0015402814 | Q10: =F10 -> -0.0094 | R10: =IF(M10<=5,"$0-$5",">$5") -> $0-$5 | S10: =IF(M10<=0.05,"$0-$0.05",IF(M10<=0.5,"$0.05-$0.5",IF(M10<=5,"$0.5-$5",IF(M10<=50,"$5-$50",">$50")))) -> $0.05-$0.5
A11: Cardano | B11: ADA | C11: $0.5808 | D11: 0.0096 | E11: =D11 -> 0.0096 | F11: =-D11 -> -0.0096 | G11: =D11 -> 0.0096 | H11: $20.54B | I11: $539,447,597 | J11: =IFERROR(VALUE(SUBSTITUTE(SUBSTITUTE(Table1[[#This Row],[Volume (24h) USD]],"$",""),",","")),0) -> 539447597 | K11: 35.36B | L11: =IF(OR(LEFT(Table1[[#This Row],[Coin Name]],1)="A",LEFT(Table1[[#This Row],[Coin Name]],1)="E",LEFT(Table1[[#This Row],[Coin Name]],1)="I",LEFT(Table1[[#This Row],[Coin Name]],1)="O",LEFT(Table1[[#This Row],[Coin Name]],1)="U",LEFT(Table1[[#This Row],[Coin Name]],1)="B",LEFT(Table1[[#This Row],[Coin Name]],1)="C",LEFT(Table1[[#This Row],[Coin Name]],1)="D"),"Yes","No") -> Yes | M11: =VALUE(SUBSTITUTE(C11,"$","")) -> 0.5808 | N11: =M11/(1+D11) -> 0.57527734 | O11: =IF(M11<10,"Up to $10",">= $10") -> Up to $10 | P11: =M11-N11 -> 0.0055226624 | Q11: =F11 -> -0.0096 | R11: =IF(M11<=5,"$0-$5",">$5") -> $0-$5 | S11: =IF(M11<=0.05,"$0-$0.05",IF(M11<=0.5,"$0.05-$0.5",IF(M11<=5,"$0.5-$5",IF(M11<=50,"$5-$50",">$50")))) -> $0.5-$5
A12: Pudgy Penguins | B12: PENGU | C12: $0.009096 | D12: 0.014 | E12: =D12 -> 0.014 | F12: =-D12 -> -0.014 | G12: =D12 -> 0.014 | H12: $571.84M | I12: $60,468,868 | J12: =IFERROR(VALUE(SUBSTITUTE(SUBSTITUTE(Table1[[#This Row],[Volume (24h) USD]],"$",""),",","")),0) -> 60468868 | K12: 62.86B | L12: =IF(OR(LEFT(Table1[[#This Row],[Coin Name]],1)="A",LEFT(Table1[[#This Row],[Coin Name]],1)="E",LEFT(Table1[[#This Row],[Coin Name]],1)="I",LEFT(Table1[[#This Row],[Coin Name]],1)="O",LEFT(Table1[[#This Row],[Coin Name]],1)="U",LEFT(Table1[[#This Row],[Coin Name]],1)="B",LEFT(Table1[[#This Row],[Coin Name]],1)="C",LEFT(Table1[[#This Row],[Coin Name]],1)="D"),"Yes","No") -> No | M12: =VALUE(SUBSTITUTE(C12,"$","")) -> 0.009096 | N12: =M12/(1+D12) -> 0.0089704142 | O12: =IF(M12<10,"Up to $10",">= $10") -> Up to $10 | P12: =M12-N12 -> 0.0001255858 | Q12: =F12 -> -0.014 | R12: =IF(M12<=5,"$0-$5",">$5") -> $0-$5 | S12: =IF(C12<=0.05,"$0-$0.05", IF(C12<=0.5,"$0.05-$0.5", IF(C12<=5,"$0.5-$5", IF(C12<=50,"$5-$50",">$50")))) -> >$50
A13: Walrus | B13: WAL | C13: $0.4205 | D13: 0.0157 | E13: =D13 -> 0.0157 | F13: =-D13 -> -0.0157 | G13: =D13 -> 0.0157 | H13: $567M | I13: $22,854,744 | J13: =IFERROR(VALUE(SUBSTITUTE(SUBSTITUTE(Table1[[#This Row],[Volume (24h) USD]],"$",""),",","")),0) -> 22854744 | K13: 1.34B | L13: =IF(OR(LEFT(Table1[[#This Row],[Coin Name]],1)="A",LEFT(Table1[[#This Row],[Coin Name]],1)="E",LEFT(Table1[[#This Row],[Coin Name]],1)="I",LEFT(Table1[[#This Row],[Coin Name]],1)="O",LEFT(Table1[[#This Row],[Coin Name]],1)="U",LEFT(Table1[[#This Row],[Coin Name]],1)="B",LEFT(Table1[[#This Row],[Coin Name]],1)="C",LEFT(Table1[[#This Row],[Coin Name]],1)="D"),"Yes","No") -> No | M13: =VALUE(SUBSTITUTE(C13,"$","")) -> 0.4205 | N13: =M13/(1+D13) -> 0.4140002 | O13: =IF(M13<10,"Up to $10",">= $10") -> Up to $10 | P13: =M13-N13 -> 0.0064998031 | Q13: =F13 -> -0.0157 | R13: =IF(M13<=5,"$0-$5",">$5") -> $0-$5 | S13: =IF(C13<=0.05,"$0-$0.05", IF(C13<=0.5,"$0.05-$0.5", IF(C13<=5,"$0.5-$5", IF(C13<=50,"$5-$50",">$50")))) -> >$50
A14: Raydium | B14: RAY | C14: $2.06 | D14: 0.0117 | E14: =D14 -> 0.0117 | F14: =-D14 -> -0.0117 | G14: =D14 -> 0.0117 | H14: $551.36M | I14: $110,228,545 | J14: =IFERROR(VALUE(SUBSTITUTE(SUBSTITUTE(Table1[[#This Row],[Volume (24h) USD]],"$",""),",","")),0) -> 110228545 | K14: 267.62M | L14: =IF(OR(LEFT(Table1[[#This Row],[Coin Name]],1)="A",LEFT(Table1[[#This Row],[Coin Name]],1)="E",LEFT(Table1[[#This Row],[Coin Name]],1)="I",LEFT(Table1[[#This Row],[Coin Name]],1)="O",LEFT(Table1[[#This Row],[Coin Name]],1)="U",LEFT(Table1[[#This Row],[Coin Name]],1)="B",LEFT(Table1[[#This Row],[Coin Name]],1)="C",LEFT(Table1[[#This Row],[Coin Name]],1)="D"),"Yes","No") -> No | M14: =VALUE(SUBSTITUTE(C14,"$","")) -> 2.06 | N14: =M14/(1+D14) -> 2.0361767 | O14: =IF(M14<10,"Up to $10",">= $10") -> Up to $10 | P14: =M14-N14 -> 0.023823268 | Q14: =F14 -> -0.0117 | R14: =IF(M14<=5,"$0-$5",">$5") -> $0-$5 | S14: =IF(C14<=0.05,"$0-$0.05", IF(C14<=0.5,"$0.05-$0.5", IF(C14<=5,"$0.5-$5", IF(C14<=50,"$5-$50",">$50")))) -> >$50
A15: Orbiter Finance | B15: OBT | C15: $0.008376 | D15: 0.0427 | E15: =D15 -> 0.0427 | F15: =-D15 -> -0.0427 | G15: =D15 -> 0.0427 | H15: $25.97M | I15: $40,860,347 | J15: =IFERROR(VALUE(SUBSTITUTE(SUBSTITUTE(Table1[[#This Row],[Volume (24h) USD]],"$",""),",","")),0) -> 40860347 | K15: 3.1B | L15: =IF(OR(LEFT(Table1[[#This Row],[Coin Name]],1)="A",LEFT(Table1[[#This Row],[Coin Name]],1)="E",LEFT(Table1[[#This Row],[Coin Name]],1)="I",LEFT(Table1[[#This Row],[Coin Name]],1)="O",LEFT(Table1[[#This Row],[Coin Name]],1)="U",LEFT(Table1[[#This Row],[Coin Name]],1)="B",LEFT(Table1[[#This Row],[Coin Name]],1)="C",LEFT(Table1[[#This Row],[Coin Name]],1)="D"),"Yes","No") -> Yes | M15: =VALUE(SUBSTITUTE(C15,"$","")) -> 0.008376 | N15: =M15/(1+D15) -> 0.0080329913 | O15: =IF(M15<10,"Up to $10",">= $10") -> Up to $10 | P15: =M15-N15 -> 0.00034300873 | Q15: =F15 -> -0.0427 | R15: =IF(M15<=5,"$0-$5",">$5") -> $0-$5 | S15: =IF(M15<=0.05,"$0-$0.05",IF(M15<=0.5,"$0.05-$0.5",IF(M15<=5,"$0.5-$5",IF(M15<=50,"$5-$50",">$50")))) -> $0-$0.05
A16: Tezos | B16: XTZ | C16: $0.5207 | D16: 0.0066 | E16: =D16 -> 0.0066 | F16: =-D16 -> -0.0066 | G16: =D16 -> 0.0066 | H16: $545.72M | I16: $14,355,952 | J16: =IFERROR(VALUE(SUBSTITUTE(SUBSTITUTE(Table1[[#This Row],[Volume (24h) USD]],"$",""),",","")),0) -> 14355952 | K16: 1.04B | L16: =IF(OR(LEFT(Table1[[#This Row],[Coin Name]],1)="A",LEFT(Table1[[#This Row],[Coin Name]],1)="E",LEFT(Table1[[#This Row],[Coin Name]],1)="I",LEFT(Table1[[#This Row],[Coin Name]],1)="O",LEFT(Table1[[#This Row],[Coin Name]],1)="U",LEFT(Table1[[#This Row],[Coin Name]],1)="B",LEFT(Table1[[#This Row],[Coin Name]],1)="C",LEFT(Table1[[#This Row],[Coin Name]],1)="D"),"Yes","No") -> No | M16: =VALUE(SUBSTITUTE(C16,"$","")) -> 0.5207 | N16: =M16/(1+D16) -> 0.51728591 | O16: =IF(M16<10,"Up to $10",">= $10") -> Up to $10 | P16: =M16-N16 -> 0.003414087 | Q16: =F16 -> -0.0066 | R16: =IF(M16<=5,"$0-$5",">$5") -> $0-$5 | S16: =IF(C16<=0.05,"$0-$0.05", IF(C16<=0.5,"$0.05-$0.5", IF(C16<=5,"$0.5-$5", IF(C16<=50,"$5-$50",">$50")))) -> >$50
A17: Pyth Network | B17: PYTH | C17: $0.09453 | D17: 0.0227 | E17: =D17 -> 0.0227 | F17: =-D17 -> -0.0227 | G17: =D17 -> 0.0227 | H17: $543.57M | I17: $27,917,564 | J17: =IFERROR(VALUE(SUBSTITUTE(SUBSTITUTE(Table1[[#This Row],[Volume (24h) USD]],"$",""),",","")),0) -> 27917564 | K17: 5.74B | L17: =IF(OR(LEFT(Table1[[#This Row],[Coin Name]],1)="A",LEFT(Table1[[#This Row],[Coin Name]],1)="E",LEFT(Table1[[#This Row],[Coin Name]],1)="I",LEFT(Table1[[#This Row],[Coin Name]],1)="O",LEFT(Table1[[#This Row],[Coin Name]],1)="U",LEFT(Table1[[#This Row],[Coin Name]],1)="B",LEFT(Table1[[#This Row],[Coin Name]],1)="C",LEFT(Table1[[#This Row],[Coin Name]],1)="D"),"Yes","No") -> No | M17: =VALUE(SUBSTITUTE(C17,"$","")) -> 0.09453 | N17: =M17/(1+D17) -> 0.092431798 | O17: =IF(M17<10,"Up to $10",">= $10") -> Up to $10 | P17: =M17-N17 -> 0.0020982018 | Q17: =F17 -> -0.0227 | R17: =IF(M17<=5,"$0-$5",">$5") -> $0-$5 | S17: =IF(C17<=0.05,"$0-$0.05", IF(C17<=0.5,"$0.05-$0.5", IF(C17<=5,"$0.5-$5", IF(C17<=50,"$5-$50",">$50")))) -> >$50
A18: Flow | B18: FLOW | C18: $0.3394 | D18: 0.01 | E18: =D18 -> 0.01 | F18: =-D18 -> -0.01 | G18: =D18 -> 0.01 | H18: $539.91M | I18: $21,157,648 | J18: =IFERROR(VALUE(SUBSTITUTE(SUBSTITUTE(Table1[[#This Row],[Volume (24h) USD]],"$",""),",","")),0) -> 21157648 | K18: 1.59B | L18: =IF(OR(LEFT(Table1[[#This Row],[Coin Name]],1)="A",LEFT(Table1[[#This Row],[Coin Name]],1)="E",LEFT(Table1[[#This Row],[Coin Name]],1)="I",LEFT(Table1[[#This Row],[Coin Name]],1)="O",LEFT(Table1[[#This Row],[Coin Name]],1)="U",LEFT(Table1[[#This Row],[Coin Name]],1)="B",LEFT(Table1[[#This Row],[Coin Name]],1)="C",LEFT(Table1[[#This Row],[Coin Name]],1)="D"),"Yes","No") -> No | M18: =VALUE(SUBSTITUTE(C18,"$","")) -> 0.3394 | N18: =M18/(1+D18) -> 0.3360396 | O18: =IF(M18<10,"Up to $10",">= $10") -> Up to $10 | P18: =M18-N18 -> 0.003360396 | Q18: =F18 -> -0.01 | R18: =IF(M18<=5,"$0-$5",">$5") -> $0-$5 | S18: =IF(C18<=0.05,"$0-$0.05", IF(C18<=0.5,"$0.05-$0.5", IF(C18<=5,"$0.5-$5", IF(C18<=50,"$5-$50",">$50")))) -> >$50
A19: Maple Finance | B19: SYRUP | C19: $0.4626 | D19: 0.0305 | E19: =D19 -> 0.0305 | F19: =-D19 -> -0.0305 | G19: =D19 -> 0.0305 | H19: $515.17M | I19: $70,946,476 | J19: =IFERROR(VALUE(SUBSTITUTE(SUBSTITUTE(Table1[[#This Row],[Volume (24h) USD]],"$",""),",","")),0) -> 70946476 | K19: 1.11B | L19: =IF(OR(LEFT(Table1[[#This Row],[Coin Name]],1)="A",LEFT(Table1[[#This Row],[Coin Name]],1)="E",LEFT(Table1[[#This Row],[Coin Name]],1)="I",LEFT(Table1[[#This Row],[Coin Name]],1)="O",LEFT(Table1[[#This Row],[Coin Name]],1)="U",LEFT(Table1[[#This Row],[Coin Name]],1)="B",LEFT(Table1[[#This Row],[Coin Name]],1)="C",LEFT(Table1[[#This Row],[Coin Name]],1)="D"),"Yes","No") -> No | M19: =VALUE(SUBSTITUTE(C19,"$","")) -> 0.4626 | N19: =M19/(1+D19) -> 0.4489083 | O19: =IF(M19<10,"Up to $10",">= $10") -> Up to $10 | P19: =M19-N19 -> 0.013691703 | Q19: =F19 -> -0.0305 | R19: =IF(M19<=5,"$0-$5",">$5") -> $0-$5 | S19: =IF(C19<=0.05,"$0-$0.05", IF(C19<=0.5,"$0.05-$0.5", IF(C19<=5,"$0.5-$5", IF(C19<=50,"$5-$50",">$50")))) -> >$50
A20: Usual | B20: USUAL | C20: $0.07198 | D20: 0.0114 | E20: =D20 -> 0.0114 | F20: =-D20 -> -0.0114 | G20: =D20 -> 0.0114 | H20: $72.72M | I20: $25,758,134 | J20: =IFERROR(VALUE(SUBSTITUTE(SUBSTITUTE(Table1[[#This Row],[Volume (24h) USD]],"$",""),",","")),0) -> 25758134 | K20: 1.01B | L20: =IF(OR(LEFT(Table1[[#This Row],[Coin Name]],1)="A",LEFT(Table1[[#This Row],[Coin Name]],1)="E",LEFT(Table1[[#This Row],[Coin Name]],1)="I",LEFT(Table1[[#This Row],[Coin Name]],1)="O",LEFT(Table1[[#This Row],[Coin Name]],1)="U",LEFT(Table1[[#This Row],[Coin Name]],1)="B",LEFT(Table1[[#This Row],[Coin Name]],1)="C",LEFT(Table1[[#This Row],[Coin Name]],1)="D"),"Yes","No") -> Yes | M20: =VALUE(SUBSTITUTE(C20,"$","")) -> 0.07198 | N20: =M20/(1+D20) -> 0.071168677 | O20: =IF(M20<10,"Up to $10",">= $10") -> Up to $10 | P20: =M20-N20 -> 0.00081132292 | Q20: =F20 -> -0.0114 | R20: =IF(M20<=5,"$0-$5",">$5") -> $0-$5 | S20: =IF(M20<=0.05,"$0-$0.05",IF(M20<=0.5,"$0.05-$0.5",IF(M20<=5,"$0.5-$5",IF(M20<=50,"$5-$50",">$50")))) -> $0.05-$0.5
A21: TrueUSD | B21: TUSD | C21: $0.9976 | D21: 0.0001 | E21: =D21 -> 0.0001 | F21: =-D21 -> -0.0001 | G21: =D21 -> 0.0001 | H21: $493.33M | I21: $60,347,807 | J21: =IFERROR(VALUE(SUBSTITUTE(SUBSTITUTE(Table1[[#This Row],[Volume (24h) USD]],"$",""),",","")),0) -> 60347807 | K21: 494.51M | L21: =IF(OR(LEFT(Table1[[#This Row],[Coin Name]],1)="A",LEFT(Table1[[#This Row],[Coin Name]],1)="E",LEFT(Table1[[#This Row],[Coin Name]],1)="I",LEFT(Table1[[#This Row],[Coin Name]],1)="O",LEFT(Table1[[#This Row],[Coin Name]],1)="U",LEFT(Table1[[#This Row],[Coin Name]],1)="B",LEFT(Table1[[#This Row],[Coin Name]],1)="C",LEFT(Table1[[#This Row],[Coin Name]],1)="D"),"Yes","No") -> No | M21: =VALUE(SUBSTITUTE(C21,"$","")) -> 0.9976 | N21: =M21/(1+D21) -> 0.99750025 | O21: =IF(M21<10,"Up to $10",">= $10") -> Up to $10 | P21: =M21-N21 -> 9.9750025e-05 | Q21: =F21 -> -0.0001 | R21: =IF(M21<=5,"$0-$5",">$5") -> $0-$5 | S21: =IF(C21<=0.05,"$0-$0.05", IF(C21<=0.5,"$0.05-$0.5", IF(C21<=5,"$0.5-$5", IF(C21<=50,"$5-$50",">$50")))) -> >$50
A22: Fasttoken | B22: FTN | C22: $4.45 | D22: 0.0001 | E22: =D22 -> 0.0001 | F22: =-D22 -> -0.0001 | G22: =D22 -> 0.0001 | H22: $1.95B | I22: $58,305,626 | J22: =IFERROR(VALUE(SUBSTITUTE(SUBSTITUTE(Table1[[#This Row],[Volume (24h) USD]],"$",""),",","")),0) -> 58305626 | K22: 436.26M | L22: =IF(OR(LEFT(Table1[[#This Row],[Coin Name]],1)="A",LEFT(Table1[[#This Row],[Coin Name]],1)="E",LEFT(Table1[[#This Row],[Coin Name]],1)="I",LEFT(Table1[[#This Row],[Coin Name]],1)="O",LEFT(Table1[[#This Row],[Coin Name]],1)="U",LEFT(Table1[[#This Row],[Coin Name]],1)="B",LEFT(Table1[[#This Row],[Coin Name]],1)="C",LEFT(Table1[[#This Row],[Coin Name]],1)="D"),"Yes","No") -> No | M22: =VALUE(SUBSTITUTE(C22,"$","")) -> 4.45 | N22: =M22/(1+D22) -> 4.449555 | O22: =IF(M22<10,"Up to $10",">= $10") -> Up to $10 | P22: =M22-N22 -> 0.0004449555 | Q22: =F22 -> -0.0001 | R22: =IF(M22<=5,"$0-$5",">$5") -> $0-$5 | S22: =IF(C22<=0.05,"$0-$0.05", IF(C22<=0.5,"$0.05-$0.5", IF(C22<=5,"$0.5-$5", IF(C22<=50,"$5-$50",">$50")))) -> >$50
A23: Jupiter Perps LP | B23: JLP | C23: $4.32 | D23: 0.0045 | E23: =D23 -> 0.0045 | F23: =-D23 -> -0.0045 | G23: =D23 -> 0.0045 | H23: $1.49B | I23: $17,245,756 | J23: =IFERROR(VALUE(SUBSTITUTE(SUBSTITUTE(Table1[[#This Row],[Volume (24h) USD]],"$",""),",","")),0) -> 17245756 | K23: 343.49M | L23: =IF(OR(LEFT(Table1[[#This Row],[Coin Name]],1)="A",LEFT(Table1[[#This Row],[Coin Name]],1)="E",LEFT(Table1[[#This Row],[Coin Name]],1)="I",LEFT(Table1[[#This Row],[Coin Name]],1)="O",LEFT(Table1[[#This Row],[Coin Name]],1)="U",LEFT(Table1[[#This Row],[Coin Name]],1)="B",LEFT(Table1[[#This Row],[Coin Name]],1)="C",LEFT(Table1[[#This Row],[Coin Name]],1)="D"),"Yes","No") -> No | M23: =VALUE(SUBSTITUTE(C23,"$","")) -> 4.32 | N23: =M23/(1+D23) -> 4.3006471 | O23: =IF(M23<10,"Up to $10",">= $10") -> Up to $10 | P23: =M23-N23 -> 0.019352912 | Q23: =F23 -> -0.0045 | R23: =IF(M23<=5,"$0-$5",">$5") -> $0-$5 | S23: =IF(C23<=0.05,"$0-$0.05", IF(C23<=0.5,"$0.05-$0.5", IF(C23<=5,"$0.5-$5", IF(C23<=50,"$5-$50",">$50")))) -> >$50
A24: Zeebu | B24: ZBU | C24: $3.26 | D24: 0.0006 | E24: =D24 -> 0.0006 | F24: =-D24 -> -0.0006 | G24: =D24 -> 0.0006 | H24: $846.7M | I24: $486,945 | J24: =IFERROR(VALUE(SUBSTITUTE(SUBSTITUTE(Table1[[#This Row],[Volume (24h) USD]],"$",""),",","")),0) -> 486945 | K24: 258.97M | L24: =IF(OR(LEFT(Table1[[#This Row],[Coin Name]],1)="A",LEFT(Table1[[#This Row],[Coin Name]],1)="E",LEFT(Table1[[#This Row],[Coin Name]],1)="I",LEFT(Table1[[#This Row],[Coin Name]],1)="O",LEFT(Table1[[#This Row],[Coin Name]],1)="U",LEFT(Table1[[#This Row],[Coin Name]],1)="B",LEFT(Table1[[#This Row],[Coin Name]],1)="C",LEFT(Table1[[#This Row],[Coin Name]],1)="D"),"Yes","No") -> No | M24: =VALUE(SUBSTITUTE(C24,"$","")) -> 3.26 | N24: =M24/(1+D24) -> 3.2580452 | O24: =IF(M24<10,"Up to $10",">= $10") -> Up to $10 | P24: =M24-N24 -> 0.0019548271 | Q24: =F24 -> -0.0006 | R24: =IF(M24<=5,"$0-$5",">$5") -> $0-$5 | S24: =IF(C24<=0.05,"$0-$0.05", IF(C24<=0.5,"$0.05-$0.5", IF(C24<=5,"$0.5-$5", IF(C24<=50,"$5-$50",">$50")))) -> >$50
A25: Fellaz | B25: FLZ | C25: $1.43 | D25: 0.0052 | E25: =D25 -> 0.0052 | F25: =-D25 -> -0.0052 | G25: =D25 -> 0.0052 | H25: $677.19M | I25: $2,595,867 | J25: =IFERROR(VALUE(SUBSTITUTE(SUBSTITUTE(Table1[[#This Row],[Volume (24h) USD]],"$",""),",","")),0) -> 2595867 | K25: 471.87M | L25: =IF(OR(LEFT(Table1[[#This Row],[Coin Name]],1)="A",LEFT(Table1[[#This Row],[Coin Name]],1)="E",LEFT(Table1[[#This Row],[Coin Name]],1)="I",LEFT(Table1[[#This Row],[Coin Name]],1)="O",LEFT(Table1[[#This Row],[Coin Name]],1)="U",LEFT(Table1[[#This Row],[Coin Name]],1)="B",LEFT(Table1[[#This Row],[Coin Name]],1)="C",LEFT(Table1[[#This Row],[Coin Name]],1)="D"),"Yes","No") -> No | M25: =VALUE(SUBSTITUTE(C25,"$","")) -> 1.43 | N25: =M25/(1+D25) -> 1.4226025 | O25: =IF(M25<10,"Up to $10",">= $10") -> Up to $10 | P25: =M25-N25 -> 0.0073975328 | Q25: =F25 -> -0.0052 | R25: =IF(M25<=5,"$0-$5",">$5") -> $0-$5 | S25: =IF(C25<=0.05,"$0-$0.05", IF(C25<=0.5,"$0.05-$0.5", IF(C25<=5,"$0.5-$5", IF(C25<=50,"$5-$50",">$50")))) -> >$50
A26: Decentraland | B26: MANA | C26: $0.2505 | D26: 0.0137 | E26: =D26 -> 0.0137 | F26: =-D26 -> -0.0137 | G26: =D26 -> 0.0137 | H26: $493.58M | I26: $25,685,731 | J26: =IFERROR(VALUE(SUBSTITUTE(SUBSTITUTE(Table1[[#This Row],[Volume (24h) USD]],"$",""),",","")),0) -> 25685731 | K26: 1.96B | L26: =IF(OR(LEFT(Table1[[#This Row],[Coin Name]],1)="A",LEFT(Table1[[#This Row],[Coin Name]],1)="E",LEFT(Table1[[#This Row],[Coin Name]],1)="I",LEFT(Table1[[#This Row],[Coin Name]],1)="O",LEFT(Table1[[#This Row],[Coin Name]],1)="U",LEFT(Table1[[#This Row],[Coin Name]],1)="B",LEFT(Table1[[#This Row],[Coin Name]],1)="C",LEFT(Table1[[#This Row],[Coin Name]],1)="D"),"Yes","No") -> Yes | M26: =VALUE(SUBSTITUTE(C26,"$","")) -> 0.2505 | N26: =M26/(1+D26) -> 0.24711453 | O26: =IF(M26<10,"Up to $10",">= $10") -> Up to $10 | P26: =M26-N26 -> 0.0033854691 | Q26: =F26 -> -0.0137 | R26: =IF(M26<=5,"$0-$5",">$5") -> $0-$5 | S26: =IF(M26<=0.05,"$0-$0.05",IF(M26<=0.5,"$0.05-$0.5",IF(M26<=5,"$0.5-$5",IF(M26<=50,"$5-$50",">$50")))) -> $0.05-$0.5
A27: Eurite | B27: EURI | C27: $1.15 | D27: 0.0007 | E27: =D27 -> 0.0007 | F27: =-D27 -> -0.0007 | G27: =D27 -> 0.0007 | H27: $51.31M | I27: $22,680,605 | J27: =IFERROR(VALUE(SUBSTITUTE(SUBSTITUTE(Table1[[#This Row],[Volume (24h) USD]],"$",""),",","")),0) -> 22680605 | K27: 44.52M | L27: =IF(OR(LEFT(Table1[[#This Row],[Coin Name]],1)="A",LEFT(Table1[[#This Row],[Coin Name]],1)="E",LEFT(Table1[[#This Row],[Coin Name]],1)="I",LEFT(Table1[[#This Row],[Coin Name]],1)="O",LEFT(Table1[[#This Row],[Coin Name]],1)="U",LEFT(Table1[[#This Row],[Coin Name]],1)="B",LEFT(Table1[[#This Row],[Coin Name]],1)="C",LEFT(Table1[[#This Row],[Coin Name]],1)="D"),"Yes","No") -> Yes | M27: =VALUE(SUBSTITUTE(C27,"$","")) -> 1.15 | N27: =M27/(1+D27) -> 1.1491956 | O27: =IF(M27<10,"Up to $10",">= $10") -> Up to $10 | P27: =M27-N27 -> 0.00080443689 | Q27: =F27 -> -0.0007 | R27: =IF(M27<=5,"$0-$5",">$5") -> $0-$5 | S27: =IF(M27<=0.05,"$0-$0.05",IF(M27<=0.5,"$0.05-$0.5",IF(M27<=5,"$0.5-$5",IF(M27<=50,"$5-$50",">$50")))) -> $0.5-$5
A28: Falcon USD | B28: USDf | C28: $0.9997 | D28: 0 | E28: =D28 -> 0 | F28: =-D28 -> 0 | G28: =D28 -> 0 | H28: $563.5M | I28: $3,265,776 | J28: =IFERROR(VALUE(SUBSTITUTE(SUBSTITUTE(Table1[[#This Row],[Volume (24h) USD]],"$",""),",","")),0) -> 3265776 | K28: 563.65M | L28: =IF(OR(LEFT(Table1[[#This Row],[Coin Name]],1)="A",LEFT(Table1[[#This Row],[Coin Name]],1)="E",LEFT(Table1[[#This Row],[Coin Name]],1)="I",LEFT(Table1[[#This Row],[Coin Name]],1)="O",LEFT(Table1[[#This Row],[Coin Name]],1)="U",LEFT(Table1[[#This Row],[Coin Name]],1)="B",LEFT(Table1[[#This Row],[Coin Name]],1)="C",LEFT(Table1[[#This Row],[Coin Name]],1)="D"),"Yes","No") -> No | M28: =VALUE(SUBSTITUTE(C28,"$","")) -> 0.9997 | N28: =M28/(1+D28) -> 0.9997 | O28: =IF(M28<10,"Up to $10",">= $10") -> Up to $10 | P28: =M28-N28 -> 0 | Q28: =F28 -> 0 | R28: =IF(M28<=5,"$0-$5",">$5") -> $0-$5 | S28: =IF(C28<=0.05,"$0-$0.05", IF(C28<=0.5,"$0.05-$0.5", IF(C28<=5,"$0.5-$5", IF(C28<=50,"$5-$50",">$50")))) -> >$50
A29: Loaded Lions | B29: LION | C29: $0.01647 | D29: 0.0052 | E29: =D29 -> 0.0052 | F29: =-D29 -> -0.0052 | G29: =D29 -> 0.0052 | H29: $546.47M | I29: $183,208 | J29: =IFERROR(VALUE(SUBSTITUTE(SUBSTITUTE(Table1[[#This Row],[Volume (24h) USD]],"$",""),",","")),0) -> 183208 | K29: 33.16B | L29: =IF(OR(LEFT(Table1[[#This Row],[Coin Name]],1)="A",LEFT(Table1[[#This Row],[Coin Name]],1)="E",LEFT(Table1[[#This Row],[Coin Name]],1)="I",LEFT(Table1[[#This Row],[Coin Name]],1)="O",LEFT(Table1[[#This Row],[Coin Name]],1)="U",LEFT(Table1[[#This Row],[Coin Name]],1)="B",LEFT(Table1[[#This Row],[Coin Name]],1)="C",LEFT(Table1[[#This Row],[Coin Name]],1)="D"),"Yes","No") -> No | M29: =VALUE(SUBSTITUTE(C29,"$","")) -> 0.01647 | N29: =M29/(1+D29) -> 0.016384799 | O29: =IF(M29<10,"Up to $10",">= $10") -> Up to $10 | P29: =M29-N29 -> 8.5200955e-05 | Q29: =F29 -> -0.0052 | R29: =IF(M29<=5,"$0-$5",">$5") -> $0-$5 | S29: =IF(C29<=0.05,"$0-$0.05", IF(C29<=0.5,"$0.05-$0.5", IF(C29<=5,"$0.5-$5", IF(C29<=50,"$5-$50",">$50")))) -> >$50
A30: would | B30: WOULD | C30: $0.4946 | D30: 0.0303 | E30: =D30 -> 0.0303 | F30: =-D30 -> -0.0303 | G30: =D30 -> 0.0303 | H30: $494.41M | I30: $138,536 | J30: =IFERROR(VALUE(SUBSTITUTE(SUBSTITUTE(Table1[[#This Row],[Volume (24h) USD]],"$",""),",","")),0) -> 138536 | K30: 999.45M | L30: =IF(OR(LEFT(Table1[[#This Row],[Coin Name]],1)="A",LEFT(Table1[[#This Row],[Coin Name]],1)="E",LEFT(Table1[[#This Row],[Coin Name]],1)="I",LEFT(Table1[[#This Row],[Coin Name]],1)="O",LEFT(Table1[[#This Row],[Coin Name]],1)="U",LEFT(Table1[[#This Row],[Coin Name]],1)="B",LEFT(Table1[[#This Row],[Coin Name]],1)="C",LEFT(Table1[[#This Row],[Coin Name]],1)="D"),"Yes","No") -> No | M30: =VALUE(SUBSTITUTE(C30,"$","")) -> 0.4946 | N30: =M30/(1+D30) -> 0.48005435 | O30: =IF(M30<10,"Up to $10",">= $10") -> Up to $10 | P30: =M30-N30 -> 0.014545647 | Q30: =F30 -> -0.0303 | R30: =IF(M30<=5,"$0-$5",">$5") -> $0-$5 | S30: =IF(C30<=0.05,"$0-$0.05", IF(C30<=0.5,"$0.05-$0.5", IF(C30<=5,"$0.5-$5", IF(C30<=50,"$5-$50",">$50")))) -> >$50
A31: WhiteRock | B31: WHITE | C31: $0.0007355 | D31: 0.0066 | E31: =D31 -> 0.0066 | F31: =-D31 -> -0.0066 | G31: =D31 -> 0.0066 | H31: $478.12M | I31: $772,538 | J31: =IFERROR(VALUE(SUBSTITUTE(SUBSTITUTE(Table1[[#This Row],[Volume (24h) USD]],"$",""),",","")),0) -> 772538 | K31: 650B | L31: =IF(OR(LEFT(Table1[[#This Row],[Coin Name]],1)="A",LEFT(Table1[[#This Row],[Coin Name]],1)="E",LEFT(Table1[[#This Row],[Coin Name]],1)="I",LEFT(Table1[[#This Row],[Coin Name]],1)="O",LEFT(Table1[[#This Row],[Coin Name]],1)="U",LEFT(Table1[[#This Row],[Coin Name]],1)="B",LEFT(Table1[[#This Row],[Coin Name]],1)="C",LEFT(Table1[[#This Row],[Coin Name]],1)="D"),"Yes","No") -> No | M31: =VALUE(SUBSTITUTE(C31,"$","")) -> 0.0007355 | N31: =M31/(1+D31) -> 0.00073067753 | O31: =IF(M31<10,"Up to $10",">= $10") -> Up to $10 | P31: =M31-N31 -> 4.8224717e-06 | Q31: =F31 -> -0.0066 | R31: =IF(M31<=5,"$0-$5",">$5") -> $0-$5 | S31: =IF(C31<=0.05,"$0-$0.05", IF(C31<=0.5,"$0.05-$0.5", IF(C31<=5,"$0.5-$5", IF(C31<=50,"$5-$50",">$50")))) -> >$50
A32: Core | B32: CORE | C32: $0.5443 | D32: 0.0082 | E32: =D32 -> 0.0082 | F32: =-D32 -> -0.0082 | G32: =D32 -> 0.0082 | H32: $546.45M | I32: $14,386,742 | J32: =IFERROR(VALUE(SUBSTITUTE(SUBSTITUTE(Table1[[#This Row],[Volume (24h) USD]],"$",""),",","")),0) -> 14386742 | K32: 1B | L32: =IF(OR(LEFT(Table1[[#This Row],[Coin Name]],1)="A",LEFT(Table1[[#This Row],[Coin Name]],1)="E",LEFT(Table1[[#This Row],[Coin Name]],1)="I",LEFT(Table1[[#This Row],[Coin Name]],1)="O",LEFT(Table1[[#This Row],[Coin Name]],1)="U",LEFT(Table1[[#This Row],[Coin Name]],1)="B",LEFT(Table1[[#This Row],[Coin Name]],1)="C",LEFT(Table1[[#This Row],[Coin Name]],1)="D"),"Yes","No") -> Yes | M32: =VALUE(SUBSTITUTE(C32,"$","")) -> 0.5443 | N32: =M32/(1+D32) -> 0.53987304 | O32: =IF(M32<10,"Up to $10",">= $10") -> Up to $10 | P32: =M32-N32 -> 0.0044269589 | Q32: =F32 -> -0.0082 | R32: =IF(M32<=5,"$0-$5",">$5") -> $0-$5 | S32: =IF(M32<=0.05,"$0-$0.05",IF(M32<=0.5,"$0.05-$0.5",IF(M32<=5,"$0.5-$5",IF(M32<=50,"$5-$50",">$50")))) -> $0.5-$5
A33: Request | B33: REQ | C33: $0.1336 | D33: 0.0032 | E33: =D33 -> 0.0032 | F33: =-D33 -> -0.0032 | G33: =D33 -> 0.0032 | H33: $110.12M | I33: $3,268,919 | J33: =IFERROR(VALUE(SUBSTITUTE(SUBSTITUTE(Table1[[#This Row],[Volume (24h) USD]],"$",""),",","")),0) -> 3268919 | K33: 824.21M | L33: =IF(OR(LEFT(Table1[[#This Row],[Coin Name]],1)="A",LEFT(Table1[[#This Row],[Coin Name]],1)="E",LEFT(Table1[[#This Row],[Coin Name]],1)="I",LEFT(Table1[[#This Row],[Coin Name]],1)="O",LEFT(Table1[[#This Row],[Coin Name]],1)="U",LEFT(Table1[[#This Row],[Coin Name]],1)="B",LEFT(Table1[[#This Row],[Coin Name]],1)="C",LEFT(Table1[[#This Row],[Coin Name]],1)="D"),"Yes","No") -> No | M33: =VALUE(SUBSTITUTE(C33,"$","")) -> 0.1336 | N33: =M33/(1+D33) -> 0.13317384 | O33: =IF(M33<10,"Up to $10",">= $10") -> Up to $10 | P33: =M33-N33 -> 0.0004261563 | Q33: =F33 -> -0.0032 | R33: =IF(M33<=5,"$0-$5",">$5") -> $0-$5 | S33: =IF(C33<=0.05,"$0-$0.05", IF(C33<=0.5,"$0.05-$0.5", IF(C33<=5,"$0.5-$5", IF(C33<=50,"$5-$50",">$50")))) -> >$50
A34: Paycoin | B34: PCI | C34: $0.1043 | D34: 0.0063 | E34: =D34 -> 0.0063 | F34: =-D34 -> -0.0063 | G34: =D34 -> 0.0063 | H34: $109.85M | I34: $4,086,544 | J34: =IFERROR(VALUE(SUBSTITUTE(SUBSTITUTE(Table1[[#This Row],[Volume (24h) USD]],"$",""),",","")),0) -> 4086544 | K34: 1.05B | L34: =IF(OR(LEFT(Table1[[#This Row],[Coin Name]],1)="A",LEFT(Table1[[#This Row],[Coin Name]],1)="E",LEFT(Table1[[#This Row],[Coin Name]],1)="I",LEFT(Table1[[#This Row],[Coin Name]],1)="O",LEFT(Table1[[#This Row],[Coin Name]],1)="U",LEFT(Table1[[#This Row],[Coin Name]],1)="B",LEFT(Table1[[#This Row],[Coin Name]],1)="C",LEFT(Table1[[#This Row],[Coin Name]],1)="D"),"Yes","No") -> No | M34: =VALUE(SUBSTITUTE(C34,"$","")) -> 0.1043 | N34: =M34/(1+D34) -> 0.10364702 | O34: =IF(M34<10,"Up to $10",">= $10") -> Up to $10 | P34: =M34-N34 -> 0.00065297625 | Q34: =F34 -> -0.0063 | R34: =IF(M34<=5,"$0-$5",">$5") -> $0-$5 | S34: =IF(C34<=0.05,"$0-$0.05", IF(C34<=0.5,"$0.05-$0.5", IF(C34<=5,"$0.5-$5", IF(C34<=50,"$5-$50",">$50")))) -> >$50
A35: Aevo | B35: AEVO | C35: $0.07876 | D35: 0.0161 | E35: =D35 -> 0.0161 | F35: =-D35 -> -0.0161 | G35: =D35 -> 0.0161 | H35: $71.27M | I35: $12,716,009 | J35: =IFERROR(VALUE(SUBSTITUTE(SUBSTITUTE(Table1[[#This Row],[Volume (24h) USD]],"$",""),",","")),0) -> 12716009 | K35: 904.86M | L35: =IF(OR(LEFT(Table1[[#This Row],[Coin Name]],1)="A",LEFT(Table1[[#This Row],[Coin Name]],1)="E",LEFT(Table1[[#This Row],[Coin Name]],1)="I",LEFT(Table1[[#This Row],[Coin Name]],1)="O",LEFT(Table1[[#This Row],[Coin Name]],1)="U",LEFT(Table1[[#This Row],[Coin Name]],1)="B",LEFT(Table1[[#This Row],[Coin Name]],1)="C",LEFT(Table1[[#This Row],[Coin Name]],1)="D"),"Yes","No") -> Yes | M35: =VALUE(SUBSTITUTE(C35,"$","")) -> 0.07876 | N35: =M35/(1+D35) -> 0.077512056 | O35: =IF(M35<10,"Up to $10",">= $10") -> Up to $10 | P35: =M35-N35 -> 0.0012479441 | Q35: =F35 -> -0.0161 | R35: =IF(M35<=5,"$0-$5",">$5") -> $0-$5 | S35: =IF(M35<=0.05,"$0-$0.05",IF(M35<=0.5,"$0.05-$0.5",IF(M35<=5,"$0.5-$5",IF(M35<=50,"$5-$50",">$50")))) -> $0.05-$0.5
A36: Gravity (by Galxe) | B36: G | C36: $0.01148 | D36: 0.0113 | E36: =D36 -> 0.0113 | F36: =-D36 -> -0.0113 | G36: =D36 -> 0.0113 | H36: $109.13M | I36: $6,571,559 | J36: =IFERROR(VALUE(SUBSTITUTE(SUBSTITUTE(Table1[[#This Row],[Volume (24h) USD]],"$",""),",","")),0) -> 6571559 | K36: 9.5B | L36: =IF(OR(LEFT(Table1[[#This Row],[Coin Name]],1)="A",LEFT(Table1[[#This Row],[Coin Name]],1)="E",LEFT(Table1[[#This Row],[Coin Name]],1)="I",LEFT(Table1[[#This Row],[Coin Name]],1)="O",LEFT(Table1[[#This Row],[Coin Name]],1)="U",LEFT(Table1[[#This Row],[Coin Name]],1)="B",LEFT(Table1[[#This Row],[Coin Name]],1)="C",LEFT(Table1[[#This Row],[Coin Name]],1)="D"),"Yes","No") -> No | M36: =VALUE(SUBSTITUTE(C36,"$","")) -> 0.01148 | N36: =M36/(1+D36) -> 0.011351726 | O36: =IF(M36<10,"Up to $10",">= $10") -> Up to $10 | P36: =M36-N36 -> 0.0001282745 | Q36: =F36 -> -0.0113 | R36: =IF(M36<=5,"$0-$5",">$5") -> $0-$5 | S36: =IF(C36<=0.05,"$0-$0.05", IF(C36<=0.5,"$0.05-$0.5", IF(C36<=5,"$0.5-$5", IF(C36<=50,"$5-$50",">$50")))) -> >$50
A37: Terra | B37: LUNA | C37: $0.1536 | D37: 0.0101 | E37: =D37 -> 0.0101 | F37: =-D37 -> -0.0101 | G37: =D37 -> 0.0101 | H37: $109.06M | I37: $11,365,168 | J37: =IFERROR(VALUE(SUBSTITUTE(SUBSTITUTE(Table1[[#This Row],[Volume (24h) USD]],"$",""),",","")),0) -> 11365168 | K37: 709.98M | L37: =IF(OR(LEFT(Table1[[#This Row],[Coin Name]],1)="A",LEFT(Table1[[#This Row],[Coin Name]],1)="E",LEFT(Table1[[#This Row],[Coin Name]],1)="I",LEFT(Table1[[#This Row],[Coin Name]],1)="O",LEFT(Table1[[#This Row],[Coin Name]],1)="U",LEFT(Table1[[#This Row],[Coin Name]],1)="B",LEFT(Table1[[#This Row],[Coin Name]],1)="C",LEFT(Table1[[#This Row],[Coin Name]],1)="D"),"Yes","No") -> No | M37: =VALUE(SUBSTITUTE(C37,"$","")) -> 0.1536 | N37: =M37/(1+D37) -> 0.15206415 | O37: =IF(M37<10,"Up to $10",">= $10") -> Up to $10 | P37: =M37-N37 -> 0.0015358479 | Q37: =F37 -> -0.0101 | R37: =IF(M37<=5,"$0-$5",">$5") -> $0-$5 | S37: =IF(C37<=0.05,"$0-$0.05", IF(C37<=0.5,"$0.05-$0.5", IF(C37<=5,"$0.5-$5", IF(C37<=50,"$5-$50",">$50")))) -> >$50
A38: Solar | B38: SXP | C38: $0.1680 | D38: 0.0029 | E38: =D38 -> 0.0029 | F38: =-D38 -> -0.0029 | G38: =D38 -> 0.0029 | H38: $108.68M | I38: $44,129,611 | J38: =IFERROR(VALUE(SUBSTITUTE(SUBSTITUTE(Table1[[#This Row],[Volume (24h) USD]],"$",""),",","")),0) -> 44129611 | K38: 646.86M | L38: =IF(OR(LEFT(Table1[[#This Row],[Coin Name]],1)="A",LEFT(Table1[[#This Row],[Coin Name]],1)="E",LEFT(Table1[[#This Row],[Coin Name]],1)="I",LEFT(Table1[[#This Row],[Coin Name]],1)="O",LEFT(Table1[[#This Row],[Coin Name]],1)="U",LEFT(Table1[[#This Row],[Coin Name]],1)="B",LEFT(Table1[[#This Row],[Coin Name]],1)="C",LEFT(Table1[[#This Row],[Coin Name]],1)="D"),"Yes","No") -> No | M38: =VALUE(SUBSTITUTE(C38,"$","")) -> 0.168 | N38: =M38/(1+D38) -> 0.16751421 | O38: =IF(M38<10,"Up to $10",">= $10") -> Up to $10 | P38: =M38-N38 -> 0.00048579121 | Q38: =F38 -> -0.0029 | R38: =IF(M38<=5,"$0-$5",">$5") -> $0-$5 | S38: =IF(C38<=0.05,"$0-$0.05", IF(C38<=0.5,"$0.05-$0.5", IF(C38<=5,"$0.5-$5", IF(C38<=50,"$5-$50",">$50")))) -> >$50
A39: AI Companions | B39: AIC | C39: $0.09574 | D39: 0.0109 | E39: =D39 -> 0.0109 | F39: =-D39 -> -0.0109 | G39: =D39 -> 0.0109 | H39: $71.81M | I39: $9,190,572 | J39: =IFERROR(VALUE(SUBSTITUTE(SUBSTITUTE(Table1[[#This Row],[Volume (24h) USD]],"$",""),",","")),0) -> 9190572 | K39: 749.99M | L39: =IF(OR(LEFT(Table1[[#This Row],[Coin Name]],1)="A",LEFT(Table1[[#This Row],[Coin Name]],1)="E",LEFT(Table1[[#This Row],[Coin Name]],1)="I",LEFT(Table1[[#This Row],[Coin Name]],1)="O",LEFT(Table1[[#This Row],[Coin Name]],1)="U",LEFT(Table1[[#This Row],[Coin Name]],1)="B",LEFT(Table1[[#This Row],[Coin Name]],1)="C",LEFT(Table1[[#This Row],[Coin Name]],1)="D"),"Yes","No") -> Yes | M39: =VALUE(SUBSTITUTE(C39,"$","")) -> 0.09574 | N39: =M39/(1+D39) -> 0.094707686 | O39: =IF(M39<10,"Up to $10",">= $10") -> Up to $10 | P39: =M39-N39 -> 0.0010323138 | Q39: =F39 -> -0.0109 | R39: =IF(M39<=5,"$0-$5",">$5") -> $0-$5 | S39: =IF(M39<=0.05,"$0-$0.05",IF(M39<=0.5,"$0.05-$0.5",IF(M39<=5,"$0.5-$5",IF(M39<=50,"$5-$50",">$50")))) -> $0.05-$0.5
A40: World Mobile Token | B40: WMTX | C40: $0.1537 | D40: 0.0054 | E40: =D40 -> 0.0054 | F40: =-D40 -> -0.0054 | G40: =D40 -> 0.0054 | H40: $108.02M | I40: $7,215,924 | J40: =IFERROR(VALUE(SUBSTITUTE(SUBSTITUTE(Table1[[#This Row],[Volume (24h) USD]],"$",""),",","")),0) -> 7215924 | K40: 702.77M | L40: =IF(OR(LEFT(Table1[[#This Row],[Coin Name]],1)="A",LEFT(Table1[[#This Row],[Coin Name]],1)="E",LEFT(Table1[[#This Row],[Coin Name]],1)="I",LEFT(Table1[[#This Row],[Coin Name]],1)="O",LEFT(Table1[[#This Row],[Coin Name]],1)="U",LEFT(Table1[[#This Row],[Coin Name]],1)="B",LEFT(Table1[[#This Row],[Coin Name]],1)="C",LEFT(Table1[[#This Row],[Coin Name]],1)="D"),"Yes","No") -> No | M40: =VALUE(SUBSTITUTE(C40,"$","")) -> 0.1537 | N40: =M40/(1+D40) -> 0.15287448 | O40: =IF(M40<10,"Up to $10",">= $10") -> Up to $10 | P40: =M40-N40 -> 0.00082552218 | Q40: =F40 -> -0.0054 | R40: =IF(M40<=5,"$0-$5",">$5") -> $0-$5 | S40: =IF(C40<=0.05,"$0-$0.05", IF(C40<=0.5,"$0.05-$0.5", IF(C40<=5,"$0.5-$5", IF(C40<=50,"$5-$50",">$50")))) -> >$50
...

Sheet task1_dashboard
D1: CRYPTO ANALYSIS DASHBOARD
A3: Coin Name | B3: Volume Num
A4: Bitcoin | B4: 43170391288 | E4: Please open in working hours (9 am to 5 pm)
A5: Ethereum | B5: 14942260356
A6: USDC | B6: 8208315257
A7: BNB | B7: 1497928447
A8: Dogecoin | B8: 781433558
A9: Cardano | B9: 539447597
A10: Orbiter Finance | B10: 40860347
A11: Usual | B11: 25758134
A12: Decentraland | B12: 25685731
A13: Eurite | B13: 22680605

Sheet Task2_Dashboard
A1: CRYPTO COIN COMPARISON DASHBOARD
A2: coin 1 name | B2: Bitcoin
A3: coin 2 name | B3: Ethereum
A6: field | B6: coin 1 | C6: coin 2
F7: Volume Difference | G7: =ABS(_xlfn.NUMBERVALUE(SUBSTITUTE(B10,"$",""))-_xlfn.NUMBERVALUE(SUBSTITUTE(C10,"$",""))) -> 28228130932
A8: symbol | B8: =_xlfn.XLOOKUP($B$2,'raw data'!$A:$A,'raw data'!$B:$B) -> BTC | C8: =_xlfn.XLOOKUP($B$3,'raw data'!$A:$A,'raw data'!$B:$B) -> ETH | F8: Market Cap Difference | G8: =B11&" vs "&C11 -> $2.07T vs $299.51B
A9: price | B9: =_xlfn.XLOOKUP($B$2,'raw data'!$A:$A,'raw data'!$C:$C) -> $104,058.04 | C9: =_xlfn.XLOOKUP($B$3,'raw data'!$A:$A,'raw data'!$C:$C) -> $2,483.59 | F9: Supply Difference | G9: =B12&" vs "&C12 -> 19.88M vs 120.72M
A10: volume | B10: =_xlfn.XLOOKUP($B$2,'raw data'!$A:$A,'raw data'!$I:$I) -> $43,170,391,288 | C10: =_xlfn.XLOOKUP($B$3,'raw data'!$A:$A,'raw data'!$I:$I) -> $14,942,260,356
A11: market cap | B11: =_xlfn.XLOOKUP($B$2,'raw data'!$A:$A,'raw data'!$H:$H) -> $2.07T | C11: =_xlfn.XLOOKUP($B$3,'raw data'!$A:$A,'raw data'!$H:$H) -> $299.51B
A12: circulating supply | B12: =_xlfn.XLOOKUP($B$2,'raw data'!$A:$A,'raw data'!$K:$K) -> 19.88M | C12: =_xlfn.XLOOKUP($B$3,'raw data'!$A:$A,'raw data'!$K:$K) -> 120.72M

Sheet Task 3_Liquidity
A1: TOP 5 CRYPTO LIQUIDITY ANALYSIS
M3: Summary table
A4: Row Labels | B4: Sum of volume num | M4: Coin | N4: Volume
A5: USDC | B5: 8208315257 | M5: USDC | N5: 8208315257
A6: $0-$50 | B6: 8208315257 | M6: Dogecoin | N6: 781433558
A7: Dogecoin | B7: 781433558 | M7: Cardano | N7: 539447597
A8: $0-$50 | B8: 781433558 | M8: Orbiter Finance | N8: 40860347
A9: Cardano | B9: 539447597 | M9: Usual | N9: 25758134
A10: $0-$50 | B10: 539447597
A11: Orbiter Finance | B11: 40860347
A12: $0-$50 | B12: 40860347
A13: Usual | B13: 25758134
A14: $0-$50 | B14: 25758134
A15: Grand Total | B15: 9595814893

Sheet Task4_Price_Analysis
A1: TOP 10 PRICE CHANGE ANALYSIS
A3: Coin Name | B3: =A8 -> Bitcoin
A4: Symbol | B4: =A9 -> BTC
A5: Price change | B5: =B8 -> 249.14136
A7: Row Labels | B7: Sum of price change
A8: Bitcoin | B8: 249.14136
A9: BTC | B9: 249.14136
A10: Ethereum | B10: 18.732914
A11: ETH | B11: 18.732914
A12: DeFi Pulse Index | B12: 2.4807333
A13: DPI | B13: 2.4807333
A14: Solana | B14: 1.398587
A15: SOL | B15: 1.398587
A16: BNB | B16: 0.64414585
A17: BNB | B17: 0.64414585
A18: Beefy | B18: 0.23469649
A19: BIFI | B19: 0.23469649
... A28: Grand Total | B28: 272.75502

Sheet Task5_Historical_Insights
A1: HISTORICAL PRICE CHANGE INSIGHTS
A2: task5 range | B2: $0-$5
A4: Row Labels | B4: Sum of 1h change | C4: Sum of 7d change | D4: Sum of 24 hr change
A5: Bitcoin 2 | B5: 0.0334 | C5: 0.0334 | D5: -0.0334
A6: Ctrl Wallet | B6: 0.1879 | C6: 0.1879 | D6: -0.1879
A7: Degen | B7: 0.0342 | C7: 0.0342 | D7: -0.0342
A8: Kin | B8: 0.0464 | C8: 0.0464 | D8: -0.0464
A9: LanLan Cat | B9: 0.1177 | C9: 0.1177 | D9: -0.1177
A10: Maple Finance | B10: 0.0305 | C10: 0.0305 | D10: -0.0305
A11: Orbiter Finance | B11: 0.0427 | C11: 0.0427 | D11: -0.0427
A12: PIBBLE | B12: 0.0405 | C12: 0.0405 | D12: -0.0405
A13: Pups (Bitcoin) | B13: 0.0424 | C13: 0.0424 | D13: -0.0424
A14: would | B14: 0.0303 | C14: 0.0303 | D14: -0.0303
A15: Grand Total | B15: 0.606 | C15: 0.606 | D15: -0.606

Sheet Task6_LowBudget_Insights
A1: Range | B1: >$50 | E1: LOW BUDGET INVESTMENT KPI DASHBOARD
A2: price range | B2: (All)
E3: coin name | F3: =A5 -> LanLan Cat
A4: Row Labels | B4: Average of average downfall | E4: symbol | F4: =VLOOKUP(F3,'raw data'!A:C,2,FALSE) -> LANLAN
A5: LanLan Cat | B5: -0.1177 | E5: price | F5: =VLOOKUP(F3,'raw data'!A:C,3,FALSE) -> $0.0001380
A6: Kin | B6: -0.0464 | E6: average downfall | F6: =B5 -> -0.1177
A7: Pups (Bitcoin) | B7: -0.0424 | E7: total coins | F7: =COUNTA(A5:A500) -> 121
A8: PIBBLE | B8: -0.0405
A9: Maple Finance | B9: -0.0305
A10: would | B10: -0.0303
A11: Torum | B11: -0.0294
A12: DeFi Pulse Index | B12: -0.0282
A13: Sentio AI | B13: -0.0267
A14: Step Finance | B14: -0.0251
A15: Hoge Finance | B15: -0.0248
A16: Spark | B16: -0.0244
A17: Pyth Network | B17: -0.0227
A18: Fractal Bitcoin | B18: -0.0219
A19: Koma Inu | B19: -0.0218
... A125: Grand Total | B125: -0.0098466667

Sheet Task3 table 
A1: Coin Name | B1: Price (USD) | C1: Volume (24h) USD | D1: volume num | E1: price range
A2: Bitcoin | B2: $104,058.04 | C2: $43,170,391,288 | D2: 43170391288 | E2: =IF(VALUE(SUBSTITUTE(B2,"$",""))<=50,"$0-$50","> $50") -> > $50
A3: Ethereum | B3: $2,483.59 | C3: $14,942,260,356 | D3: 14942260356 | E3: =IF(VALUE(SUBSTITUTE(B3,"$",""))<=50,"$0-$50","> $50") -> > $50
A4: USDC | B4: $0.9998 | C4: $8,208,315,257 | D4: 8208315257 | E4: =IF(VALUE(SUBSTITUTE(B4,"$",""))<=50,"$0-$50","> $50") -> $0-$50
A5: BNB | B5: $644.79 | C5: $1,497,928,447 | D5: 1497928447 | E5: =IF(VALUE(SUBSTITUTE(B5,"$",""))<=50,"$0-$50","> $50") -> > $50
A6: Dogecoin | B6: $0.1654 | C6: $781,433,558 | D6: 781433558 | E6: =IF(VALUE(SUBSTITUTE(B6,"$",""))<=50,"$0-$50","> $50") -> $0-$50
A7: Cardano | B7: $0.5808 | C7: $539,447,597 | D7: 539447597 | E7: =IF(VALUE(SUBSTITUTE(B7,"$",""))<=50,"$0-$50","> $50") -> $0-$50
A8: Orbiter Finance | B8: $0.008376 | C8: $40,860,347 | D8: 40860347 | E8: =IF(VALUE(SUBSTITUTE(B8,"$",""))<=50,"$0-$50","> $50") -> $0-$50
A9: Usual | B9: $0.07198 | C9: $25,758,134 | D9: 25758134 | E9: =IF(VALUE(SUBSTITUTE(B9,"$",""))<=50,"$0-$50","> $50") -> $0-$50
A10: Decentraland | B10: $0.2505 | C10: $25,685,731 | D10: 25685731 | E10: =IF(VALUE(SUBSTITUTE(B10,"$",""))<=50,"$0-$50","> $50") -> $0-$50
A11: Eurite | B11: $1.15 | C11: $22,680,605 | D11: 22680605 | E11: =IF(VALUE(SUBSTITUTE(B11,"$",""))<=50,"$0-$50","> $50") -> $0-$50
A12: Core | B12: $0.5443 | C12: $14,386,742 | D12: 14386742 | E12: =IF(VALUE(SUBSTITUTE(B12,"$",""))<=50,"$0-$50","> $50") -> $0-$50
A13: Aevo | B13: $0.07876 | C13: $12,716,009 | D13: 12716009 | E13: =IF(VALUE(SUBSTITUTE(B13,"$",""))<=50,"$0-$50","> $50") -> $0-$50
... A87: DeHub | B87: $0.0003842 | C87: N/A | D87: 0 | E87: =IF(VALUE(SUBSTITUTE(B87,"$",""))<=50,"$0-$50","> $50") -> $0-$50
